Workbook

Sheet SETTINGS
A1: SETTINGS – Core Assumptions
A3: Sell-Side Costs (as % of ARV)
A4: Realtor commission | B4: 0.05
A5: Seller closing costs | B5: 0.02
A6: Holding cost (monthly) | B6: 0.01
A7: Est. hold period (months) | B7: 6
A9: Wholesale / Offer Margins
A10: Classic MAO % of ARV | B10: 0.7
A11: Tight deal MAO % | B11: 0.65
A12: Target buyer profit % | B12: 0.15
A13: Min assignment fee ($) | B13: 10000
A14: Opening offer discount % | B14: 0.2
A15: Target offer discount % | B15: 0.1
A16: Absolute max buffer % | B16: 0.02
A18: Quick Rehab Cost-per-SqFt Tiers
A19: Light cosmetic ($/sqft) | B19: 15
A20: Moderate rehab ($/sqft) | B20: 30
A21: Heavy rehab ($/sqft) | B21: 50
A22: Full gut / structural ($/sqft) | B22: 75
A24: Dallas Buy-Box Filters (v2)
A25: Target zip codes | B25: 75215, 75216, 75217, 75223, 75227
A26: Min ARV ($) | B26: 80000
A27: Max ARV ($) | B27: 250000
A28: Max seller ask ($) | B28: 150000
A29: Max rehab ($) | B29: 60000

Sheet COMPS
A1: COMPS – Comparable Sales ARV Builder
A3: Field | B3: Comp 1 | C3: Comp 2 | D3: Comp 3 | E3: Comp 4 | F3: Comp 5 | G3: Comp 6
A4: Address
A5: Sale price
A6: Sq ft
A7: Price / sqft | B7: =IF(B5=0,"",B5/B6) | C7: =IF(C5=0,"",C5/C6) | D7: =IF(D5=0,"",D5/D6) | E7: =IF(E5=0,"",E5/E6) | F7: =IF(F5=0,"",F5/F6) | G7: =IF(G5=0,"",G5/G6)
A8: Bed / Bath
A9: Year built
A10: Days on market
A11: Condition adj (+/-)
A12: Adjusted price | B12: =IF(B5=0,0,B5+B11) | C12: =IF(C5=0,0,C5+C11) | D12: =IF(D5=0,0,D5+D11) | E12: =IF(E5=0,0,E5+E11) | F12: =IF(F5=0,0,F5+F11) | G12: =IF(G5=0,0,G5+G11)
A14: ARV Summary
A15: Average adjusted price | B15: =AVERAGEIF(B12:G12,">0")
A16: Median adjusted price | B16: =MEDIAN(IF(B12:G12>0,B12:G12))
A17: Comp-based ARV (avg) | B17: =B15

Sheet REPAIRS
A1: REPAIRS – Rehab Cost Estimator
A3: Quick Estimate (by condition tier)
A4: Square footage | B4: 1400
A5: Condition tier | B5: Moderate
A6: Cost per sqft (from SETTINGS) | B6: =IF(B5="Light",SETTINGS!B19,IF(B5="Moderate",SETTINGS!B20,IF(B5="Heavy",SETTINGS!B21,SETTINGS!B22)))
A7: Quick rehab total | B7: =B4*B6
A9: Detailed Line-Item Rehab
A10: Category | B10: Description | C10: Qty | D10: Unit Cost | E10: Line Total
A11: Roof | B11: Tear-off + reshingle | C11: 1 | D11: 7500 | E11: =C11*D11
A12: HVAC | B12: Replace full system | C12: 1 | D12: 5500 | E12: =C12*D12
A13: Plumbing | B13: Repipe / repair | C13: 1 | D13: 3500 | E13: =C13*D13
A14: Electrical | B14: Panel + rewire | C14: 1 | D14: 4000 | E14: =C14*D14
A15: Foundation | B15: Pier / level | C15: 1 | D15: 5000 | E15: =C15*D15
A16: Exterior paint | B16: Full exterior | C16: 1 | D16: 3000 | E16: =C16*D16
A17: Interior paint | B17: Full interior | C17: 1 | D17: 2500 | E17: =C17*D17
A18: Flooring | B18: LVP / tile install | C18: 1400 | D18: 3 | E18: =C18*D18
A19: Kitchen | B19: Cabinets + counters + appliances | C19: 1 | D19: 8000 | E19: =C19*D19
A20: Bathrooms | B20: Full bath reno x2 | C20: 2 | D20: 4000 | E20: =C20*D20
A21: Windows | B21: Replace all | C21: 10 | D21: 350 | E21: =C21*D21
A22: Landscaping | B22: Clean-up + sod | C22: 1 | D22: 1500 | E22: =C22*D22
... A24: Permits / misc | B24: City permits + contingency | C24: 1 | D24: 2000 | E24: =C24*D24
A26: DETAILED REHAB TOTAL | E26: =SUM(E11:E24)
A28: Rehab Estimate to Use
A29: Use detailed if available? | B29: Yes
A30: Selected rehab estimate | B30: =IF(B29="Yes",E26,B7)

Sheet DEAL_CALC
A1: DEAL CALCULATOR – Underwriting
A3: Property Information
A4: Property address
A5: City / Zip | B5: Dallas, TX
A6: County | B6: Dallas
A7: Sq ft | B7: 1400
A8: Beds / Baths | B8: 3 / 2
A9: Year built | B9: 1965
A10: Lot size (sqft) | B10: 6500
A11: Seller ask price | B11: 85000
A13: After-Repair Value (ARV)
A14: Comp-based ARV (from COMPS) | B14: =COMPS!B17
A15: Manual ARV override | B15: 180000
A16: ARV to use | B16: =IF(B15>0,B15,B14)
A18: Repair Estimate
A19: Rehab estimate (from REPAIRS) | B19: =REPAIRS!B30
A21: Classic MAO / ROS Ceiling
A22: MAO % of ARV (from SETTINGS) | B22: =SETTINGS!B10
A23: Classic MAO ceiling | B23: =(B16*B22)-B19
A25: Precision Investor-Max Ceiling
A26: Realtor commission | B26: =B16*SETTINGS!B4
A27: Seller closing costs | B27: =B16*SETTINGS!B5
A28: Hold costs (total) | B28: =B16*SETTINGS!B6*SETTINGS!B7
A29: Repairs | B29: =B19
A30: Target buyer profit | B30: =B16*SETTINGS!B12
A31: Total investor costs | B31: =SUM(B26:B30)
A32: Precision investor max | B32: =B16-B31
A34: Recommended Contract Ceiling
A35: Classic MAO ceiling | B35: =B23
A36: Precision investor max | B36: =B32
A37: CONTRACT CEILING (lower of two) | B37: =MIN(B35,B36)
A39: Offer Strategy
A40: Opening offer | B40: =B37*(1-SETTINGS!B14)
A41: Target offer | B41: =B37*(1-SETTINGS!B15)
A42: Absolute max offer | B42: =B37*(1-SETTINGS!B16)
A44: Assignment / Wholesale Spread
A45: Contract price (your offer)
A46: Investor buyer price | B46: =B32
A47: Assignment fee | B47: =B46-B45
A48: Min assignment fee (SETTINGS) | B48: =SETTINGS!B13
...

Sheet DISPO_SUMMARY
A1: BUYER DEAL SUMMARY
A3: Property Details | D3: Notes for Buyer
A4: Address | B4: =DEAL_CALC!B4 | D4: Comparable sales | E4: See COMPS tab
A5: City / Zip | B5: =DEAL_CALC!B5 | D5: Scope of work | E5: See REPAIRS tab
A6: Sq ft | B6: =DEAL_CALC!B7 | D6: Title status | E6: Clear — see title report
A7: Beds / Baths | B7: =DEAL_CALC!B8 | D7: Assignment / close date | E7: TBD
A8: Year built | B8: =DEAL_CALC!B9 | D8: EMD required | E8: $2,000
A10: Investment Numbers
A11: ARV | B11: =DEAL_CALC!B16
A12: Est. rehab | B12: =DEAL_CALC!B19
A13: Purchase price | B13: =DEAL_CALC!B46
A14: Total investment | B14: =DEAL_CALC!B46+DEAL_CALC!B19
A15: Projected profit | B15: =DEAL_CALC!B16-DEAL_CALC!B31-DEAL_CALC!B46
A16: Est. ROI | B16: =DEAL_CALC!B50
A18: DISCLAIMER: This summary is for informational purposes only and does not constitute legal, tax, or investment advice. Buyer should conduct independent due diligence. All figures are estimates and may vary. Consult licensed professionals before closing.
